<?xml version="1.0" encoding="utf-8"?>
<!-- This URDF was automatically created by SolidWorks to URDF Exporter! Originally created by Stephen Brawner (brawner@gmail.com) 
     Commit Version: 1.6.0-4-g7f85cfe  Build Version: 1.6.7995.38578
     For more information, please see http://wiki.ros.org/sw_urdf_exporter -->
<robot
  name="m20id_35">
  <link
    name="base_ground">
    <visual>
      <origin
        xyz="0 0 0"
        rpy="0 0 0" />
      <geometry>
        <box size="0.001 0.001 0.001" />
      </geometry>
    </visual>
    <collision>
      <origin
        xyz="0 0 0"
        rpy="0 0 0" />
      <geometry>
        <box size="0.001 0.001 0.001" />
      </geometry>
    </collision>
  </link>

  <joint 
    name = "arm1_base"
    type="fixed">
    <origin
      xyz="-1 0.75 0.3"
      rpy="0 0 0" />
    <parent
      link="base_ground" />
    <child
      link="base_link_1" />
  </joint>

  <joint 
    name = "arm2_base"
    type="fixed">
    <origin
      xyz="1 -0.75 0.3"
      rpy="0 0 3.1416" />
    <parent
      link="base_ground" />
    <child
      link="base_link_2" />
  </joint>
  
  <link
    name="base_link_1">
    <inertial>
      <origin
        xyz="-0.023633 0.0038198 0.098793"
        rpy="0 0 0" />
      <mass
        value="5.1351" />
      <inertia
        ixx="0.06095"
        ixy="0.00084571"
        ixz="0.0044562"
        iyy="0.081423"
        iyz="0.00050805"
        izz="0.11291" />
    </inertial>
    <visual>
      <origin
        xyz="0 0 0"
        rpy="0 0 0" />
      <geometry>
        <mesh
          filename="package://m20id_35/meshes/base_link.STL" />
      </geometry>
      <material
        name="">
        <color
          rgba="1 1 1 1" />
      </material>
    </visual>
    <collision>
      <origin
        xyz="0 0 0"
        rpy="0 0 0" />
      <geometry>
        <mesh
          filename="package://m20id_35/meshes/base_link.STL" />
      </geometry>
    </collision>
  </link>
  <link
    name="shoulder_link_1">
    <inertial>
      <origin
        xyz="0.011327 0.02343 0.17427"
        rpy="0 0 0" />
      <mass
        value="18.964" />
      <inertia
        ixx="0.33663"
        ixy="0.027541"
        ixz="-0.014122"
        iyy="0.34346"
        iyz="-0.040558"
        izz="0.30546" />
    </inertial>
    <visual>
      <origin
        xyz="0 0 0"
        rpy="0 0 0" />
      <geometry>
        <mesh
          filename="package://m20id_35/meshes/shoulder_link.STL" />
      </geometry>
      <material
        name="">
        <color
          rgba="1 1 1 1" />
      </material>
    </visual>
    <collision>
      <origin
        xyz="0 0 0"
        rpy="0 0 0" />
      <geometry>
        <mesh
          filename="package://m20id_35/meshes/shoulder_link.STL" />
      </geometry>
    </collision>
  </link>
  <joint
    name="joint11"
    type="revolute">
    <origin
      xyz="0 0 0.157"
      rpy="0 0 0" />
    <parent
      link="base_link_1" />
    <child
      link="shoulder_link_1" />
    <axis
      xyz="0 0 1" />
    <limit
      lower="-3.2289"
      upper="3.2289"
      effort="0"
      velocity="3.1416" />
  </joint>
  <link
    name="arm_link_1">
    <inertial>
      <origin
        xyz="-0.047138 -0.35456 -0.10163"
        rpy="0 0 0" />
      <mass
        value="20.745" />
      <inertia
        ixx="1.9258"
        ixy="-0.048401"
        ixz="-0.023229"
        iyy="0.12979"
        iyz="0.033424"
        izz="1.9688" />
    </inertial>
    <visual>
      <origin
        xyz="0 0 0"
        rpy="0 0 0" />
      <geometry>
        <mesh
          filename="package://m20id_35/meshes/arm_link.STL" />
      </geometry>
      <material
        name="">
        <color
          rgba="1 1 1 1" />
      </material>
    </visual>
    <collision>
      <origin
        xyz="0 0 0"
        rpy="0 0 0" />
      <geometry>
        <mesh
          filename="package://m20id_35/meshes/arm_link.STL" />
      </geometry>
    </collision>
  </link>
  <joint
    name="joint12"
    type="revolute">
    <origin
      xyz="0.075 -0.08002 0.268"
      rpy="-1.5708 0 0" />
    <parent
      link="shoulder_link_1" />
    <child
      link="arm_link_1" />
    <axis
      xyz="0 0 1" />
    <limit
      lower="-2.7925"
      upper="1.7453"
      effort="0"
      velocity="3.1416" />
  </joint>
  <link
    name="elbow_link_1">
    <inertial>
      <origin
        xyz="0.141588666664855 0.112618321023093 -0.0988430813988773"
        rpy="0 0 0" />
      <mass
        value="13.8445960856355" />
      <inertia
        ixx="0.235600580832625"
        ixy="-0.096601957743727"
        ixz="0.0140558208333844"
        iyy="0.228747824200201"
        iyz="0.00120225373081753"
        izz="0.281447186701807" />
    </inertial>
    <visual>
      <origin
        xyz="0 0 0"
        rpy="0 0 0" />
      <geometry>
        <mesh
          filename="package://m20id_35/meshes/elbow_link.STL" />
      </geometry>
      <material
        name="">
        <color
          rgba="1 1 1 1" />
      </material>
    </visual>
    <collision>
      <origin
        xyz="0 0 0"
        rpy="0 0 0" />
      <geometry>
        <mesh
          filename="package://m20id_35/meshes/elbow_link.STL" />
      </geometry>
    </collision>
  </link>
  <joint
    name="joint13"
    type="revolute">
    <origin
      xyz="0 -0.84 0.01752"
      rpy="-3.1416 0 0" />
    <parent
      link="arm_link_1" />
    <child
      link="elbow_link_1" />
    <axis
      xyz="0 0 1" />
    <limit
      lower="-3.3161"
      upper="4.6775"
      effort="0"
      velocity="3.4907" />
  </joint>
  <link
    name="forearm_link_1">
    <inertial>
      <origin
        xyz="-0.063255 -0.0002881 0.27256"
        rpy="0 0 0" />
      <mass
        value="8.6186" />
      <inertia
        ixx="0.099253"
        ixy="-2.3706E-06"
        ixz="0.0099493"
        iyy="0.1009"
        iyz="-2.2342E-05"
        izz="0.028818" />
    </inertial>
    <visual>
      <origin
        xyz="0 0 0"
        rpy="0 0 0" />
      <geometry>
        <mesh
          filename="package://m20id_35/meshes/forearm_link.STL" />
      </geometry>
      <material
        name="">
        <color
          rgba="1 1 1 1" />
      </material>
    </visual>
    <collision>
      <origin
        xyz="0 0 0"
        rpy="0 0 0" />
      <geometry>
        <mesh
          filename="package://m20id_35/meshes/forearm_link.STL" />
      </geometry>
    </collision>
  </link>
  <joint
    name="joint14"
    type="revolute">
    <origin
      xyz="0.29574 0.215 -0.0625"
      rpy="0 1.5708 0" />
    <parent
      link="elbow_link_1" />
    <child
      link="forearm_link_1" />
    <axis
      xyz="0 0 1" />
    <limit
      lower="-3.4907"
      upper="3.4907"
      effort="0"
      velocity="6.1087" />
  </joint>
  <link
    name="wrist_link_1">
    <inertial>
      <origin
        xyz="0.030158 1.739E-06 -0.032589"
        rpy="0 0 0" />
      <mass
        value="0.50503" />
      <inertia
        ixx="0.0013329"
        ixy="1.9227E-08"
        ixz="0.00033609"
        iyy="0.0012932"
        iyz="-9.9325E-09"
        izz="0.0015121" />
    </inertial>
    <visual>
      <origin
        xyz="0 0 0"
        rpy="0 0 0" />
      <geometry>
        <mesh
          filename="package://m20id_35/meshes/wrist_link.STL" />
      </geometry>
      <material
        name="">
        <color
          rgba="0.2 0.2 0.2 1" />
      </material>
    </visual>
    <collision>
      <origin
        xyz="0 0 0"
        rpy="0 0 0" />
      <geometry>
        <mesh
          filename="package://m20id_35/meshes/wrist_link.STL" />
      </geometry>
    </collision>
  </link>
  <joint
    name="joint15"
    type="revolute">
    <origin
      xyz="-0.0525 0 0.59426"
      rpy="0 -1.5708 0" />
    <parent
      link="forearm_link_1" />
    <child
      link="wrist_link_1" />
    <axis
      xyz="0 0 1" />
    <limit
      lower="-3.1416"
      upper="3.1416"
      effort="0"
      velocity="6.1087" />
  </joint>
  <link
    name="hand_link_1">
    <inertial>
      <origin
        xyz="5.1083E-18 -4.4409E-16 0.02528"
        rpy="0 0 0" />
      <mass
        value="0.14987" />
      <inertia
        ixx="0.00013695"
        ixy="-2.3225E-16"
        ixz="-1.0056E-20"
        iyy="0.00013691"
        iyz="-7.0219E-20"
        izz="0.00020789" />
    </inertial>
    <visual>
      <origin
        xyz="0 0 0"
        rpy="0 0 0" />
      <geometry>
        <mesh
          filename="package://m20id_35/meshes/hand_link.STL" />
      </geometry>
      <material
        name="">
        <color
          rgba="1 1 1 1" />
      </material>
    </visual>
    <collision>
      <origin
        xyz="0 0 0"
        rpy="0 0 0" />
      <geometry>
        <mesh
          filename="package://m20id_35/meshes/hand_link.STL" />
      </geometry>
    </collision>
  </link>
  <joint
    name="joint16"
    type="revolute">
    <origin
      xyz="0.0308 0 -0.0525"
      rpy="0 1.5708 0" />
    <parent
      link="wrist_link_1" />
    <child
      link="hand_link_1" />
    <axis
      xyz="0 0 1" />
    <limit
      lower="-7.854"
      upper="7.854"
      effort="0"
      velocity="6.9813" />
  </joint>




  <joint
    name="joint17"
    type="fixed">
    <origin
      xyz="0 0 0.08"
      rpy="0 0 0" />
    <parent
      link="hand_link_1" />
    <child
      link="detector" />
  </joint>

  <link
    name="detector">
    <inertial>
      <origin
        xyz="-1.7388E-06 -0.030158 0.032589"
        rpy="0 0 0" />
      <mass
        value="0.50503" />
      <inertia
        ixx="0.0012932"
        ixy="1.9229E-08"
        ixz="-9.9312E-09"
        iyy="0.0013329"
        iyz="0.00033609"
        izz="0.0015121" />
    </inertial>
    <visual>
      <origin
        xyz="0 0 0"
        rpy="0 0 0" />
      <geometry>
        <mesh
          filename="package://m20id_35/meshes/detector.STL" />
      </geometry>
      <material
        name="">
        <color
          rgba="0.3 0.3 0.3 1" />
      </material>
    </visual>
    <collision>
      <origin
        xyz="0 0 0"
        rpy="0 0 0" />
      <geometry>
        <mesh
          filename="package://m20id_35/meshes/detector.STL" />
      </geometry>
    </collision>
  </link>



  <link
    name="base_link_2">
    <inertial>
      <origin
        xyz="-0.023633 0.0038198 0.098793"
        rpy="0 0 0" />
      <mass
        value="5.1351" />
      <inertia
        ixx="0.06095"
        ixy="0.00084571"
        ixz="0.0044562"
        iyy="0.081423"
        iyz="0.00050805"
        izz="0.11291" />
    </inertial>
    <visual>
      <origin
        xyz="0 0 0"
        rpy="0 0 0" />
      <geometry>
        <mesh
          filename="package://m20id_35/meshes/base_link.STL" />
      </geometry>
      <material
        name="">
        <color
          rgba="1 1 1 1" />
      </material>
    </visual>
    <collision>
      <origin
        xyz="0 0 0"
        rpy="0 0 0" />
      <geometry>
        <mesh
          filename="package://m20id_35/meshes/base_link.STL" />
      </geometry>
    </collision>
  </link>
  <link
    name="shoulder_link_2">
    <inertial>
      <origin
        xyz="0.011327 0.02343 0.17427"
        rpy="0 0 0" />
      <mass
        value="18.964" />
      <inertia
        ixx="0.33663"
        ixy="0.027541"
        ixz="-0.014122"
        iyy="0.34346"
        iyz="-0.040558"
        izz="0.30546" />
    </inertial>
    <visual>
      <origin
        xyz="0 0 0"
        rpy="0 0 0" />
      <geometry>
        <mesh
          filename="package://m20id_35/meshes/shoulder_link.STL" />
      </geometry>
      <material
        name="">
        <color
          rgba="1 1 1 1" />
      </material>
    </visual>
    <collision>
      <origin
        xyz="0 0 0"
        rpy="0 0 0" />
      <geometry>
        <mesh
          filename="package://m20id_35/meshes/shoulder_link.STL" />
      </geometry>
    </collision>
  </link>
  <joint
    name="joint21"
    type="revolute">
    <origin
      xyz="0 0 0.157"
      rpy="0 0 0" />
    <parent
      link="base_link_2" />
    <child
      link="shoulder_link_2" />
    <axis
      xyz="0 0 1" />
    <limit
      lower="-3.2289"
      upper="3.2289"
      effort="0"
      velocity="3.1416" />
  </joint>
  <link
    name="arm_link_2">
    <inertial>
      <origin
        xyz="-0.047138 -0.35456 -0.10163"
        rpy="0 0 0" />
      <mass
        value="20.745" />
      <inertia
        ixx="1.9258"
        ixy="-0.048401"
        ixz="-0.023229"
        iyy="0.12979"
        iyz="0.033424"
        izz="1.9688" />
    </inertial>
    <visual>
      <origin
        xyz="0 0 0"
        rpy="0 0 0" />
      <geometry>
        <mesh
          filename="package://m20id_35/meshes/arm_link.STL" />
      </geometry>
      <material
        name="">
        <color
          rgba="1 1 1 1" />
      </material>
    </visual>
    <collision>
      <origin
        xyz="0 0 0"
        rpy="0 0 0" />
      <geometry>
        <mesh
          filename="package://m20id_35/meshes/arm_link.STL" />
      </geometry>
    </collision>
  </link>
  <joint
    name="joint22"
    type="revolute">
    <origin
      xyz="0.075 -0.08002 0.268"
      rpy="-1.5708 0 0" />
    <parent
      link="shoulder_link_2" />
    <child
      link="arm_link_2" />
    <axis
      xyz="0 0 1" />
    <limit
      lower="-2.7925"
      upper="1.7453"
      effort="0"
      velocity="3.1416" />
  </joint>
  <link
    name="elbow_link_2">
    <inertial>
      <origin
        xyz="0.141588666664855 0.112618321023093 -0.0988430813988773"
        rpy="0 0 0" />
      <mass
        value="13.8445960856355" />
      <inertia
        ixx="0.235600580832625"
        ixy="-0.096601957743727"
        ixz="0.0140558208333844"
        iyy="0.228747824200201"
        iyz="0.00120225373081753"
        izz="0.281447186701807" />
    </inertial>
    <visual>
      <origin
        xyz="0 0 0"
        rpy="0 0 0" />
      <geometry>
        <mesh
          filename="package://m20id_35/meshes/elbow_link.STL" />
      </geometry>
      <material
        name="">
        <color
          rgba="1 1 1 1" />
      </material>
    </visual>
    <collision>
      <origin
        xyz="0 0 0"
        rpy="0 0 0" />
      <geometry>
        <mesh
          filename="package://m20id_35/meshes/elbow_link.STL" />
      </geometry>
    </collision>
  </link>
  <joint
    name="joint23"
    type="revolute">
    <origin
      xyz="0 -0.84 0.01752"
      rpy="-3.1416 0 0" />
    <parent
      link="arm_link_2" />
    <child
      link="elbow_link_2" />
    <axis
      xyz="0 0 1" />
    <limit
      lower="-3.3161"
      upper="4.6775"
      effort="0"
      velocity="3.4907" />
  </joint>
  <link
    name="forearm_link_2">
    <inertial>
      <origin
        xyz="-0.063255 -0.0002881 0.27256"
        rpy="0 0 0" />
      <mass
        value="8.6186" />
      <inertia
        ixx="0.099253"
        ixy="-2.3706E-06"
        ixz="0.0099493"
        iyy="0.1009"
        iyz="-2.2342E-05"
        izz="0.028818" />
    </inertial>
    <visual>
      <origin
        xyz="0 0 0"
        rpy="0 0 0" />
      <geometry>
        <mesh
          filename="package://m20id_35/meshes/forearm_link.STL" />
      </geometry>
      <material
        name="">
        <color
          rgba="1 1 1 1" />
      </material>
    </visual>
    <collision>
      <origin
        xyz="0 0 0"
        rpy="0 0 0" />
      <geometry>
        <mesh
          filename="package://m20id_35/meshes/forearm_link.STL" />
      </geometry>
    </collision>
  </link>
  <joint
    name="joint24"
    type="revolute">
    <origin
      xyz="0.29574 0.215 -0.0625"
      rpy="0 1.5708 0" />
    <parent
      link="elbow_link_2" />
    <child
      link="forearm_link_2" />
    <axis
      xyz="0 0 1" />
    <limit
      lower="-3.4907"
      upper="3.4907"
      effort="0"
      velocity="6.1087" />
  </joint>
  <link
    name="wrist_link_2">
    <inertial>
      <origin
        xyz="0.030158 1.739E-06 -0.032589"
        rpy="0 0 0" />
      <mass
        value="0.50503" />
      <inertia
        ixx="0.0013329"
        ixy="1.9227E-08"
        ixz="0.00033609"
        iyy="0.0012932"
        iyz="-9.9325E-09"
        izz="0.0015121" />
    </inertial>
    <visual>
      <origin
        xyz="0 0 0"
        rpy="0 0 0" />
      <geometry>
        <mesh
          filename="package://m20id_35/meshes/wrist_link.STL" />
      </geometry>
      <material
        name="">
        <color
          rgba="0.2 0.2 0.2 1" />
      </material>
    </visual>
    <collision>
      <origin
        xyz="0 0 0"
        rpy="0 0 0" />
      <geometry>
        <mesh
          filename="package://m20id_35/meshes/wrist_link.STL" />
      </geometry>
    </collision>
  </link>
  <joint
    name="joint25"
    type="revolute">
    <origin
      xyz="-0.0525 0 0.59426"
      rpy="0 -1.5708 0" />
    <parent
      link="forearm_link_2" />
    <child
      link="wrist_link_2" />
    <axis
      xyz="0 0 1" />
    <limit
      lower="-3.1416"
      upper="3.1416"
      effort="0"
      velocity="6.1087" />
  </joint>
  <link
    name="hand_link_2">
    <inertial>
      <origin
        xyz="5.1083E-18 -4.4409E-16 0.02528"
        rpy="0 0 0" />
      <mass
        value="0.14987" />
      <inertia
        ixx="0.00013695"
        ixy="-2.3225E-16"
        ixz="-1.0056E-20"
        iyy="0.00013691"
        iyz="-7.0219E-20"
        izz="0.00020789" />
    </inertial>
    <visual>
      <origin
        xyz="0 0 0"
        rpy="0 0 0" />
      <geometry>
        <mesh
          filename="package://m20id_35/meshes/hand_link.STL" />
      </geometry>
      <material
        name="">
        <color
          rgba="1 1 1 1" />
      </material>
    </visual>
    <collision>
      <origin
        xyz="0 0 0"
        rpy="0 0 0" />
      <geometry>
        <mesh
          filename="package://m20id_35/meshes/hand_link.STL" />
      </geometry>
    </collision>
  </link>
  <joint
    name="joint26"
    type="revolute">
    <origin
      xyz="0.0308 0 -0.0525"
      rpy="0 1.5708 0" />
    <parent
      link="wrist_link_2" />
    <child
      link="hand_link_2" />
    <axis
      xyz="0 0 1" />
    <limit
      lower="-7.854"
      upper="7.854"
      effort="0"
      velocity="6.9813" />
  </joint>



  <joint
    name="joint27"
    type="fixed">
    <origin
      xyz="0.0 0 0.1"
      rpy="-1.5708 0 -1.5708" />
    <parent
      link="hand_link_2" />
    <child
      link="x_ray_generator" />
  </joint>

  <link
    name="x_ray_generator">
    <inertial>
      <origin
        xyz="-1.7388E-06 -0.030158 0.032589"
        rpy="0 0 0" />
      <mass
        value="0.50503" />
      <inertia
        ixx="0.0012932"
        ixy="1.9229E-08"
        ixz="-9.9312E-09"
        iyy="0.0013329"
        iyz="0.00033609"
        izz="0.0015121" />
    </inertial>
    <visual>
      <origin
        xyz="0 0 0"
        rpy="0 0 0" />
      <geometry>
        <mesh
          filename="package://m20id_35/meshes/MXR225MF.STL" scale = "0.001 0.001 0.001"/>
      </geometry>
      <material
        name="">
        <color
          rgba="0.7 0.7 0.7 1" />
      </material>
    </visual>
    <collision>
      <origin
        xyz="0 0 0"
        rpy="0 0 0" />
      <geometry>
        <mesh
          filename="package://m20id_35/meshes/MXR225MF.STL"  scale = "0.001 0.001 0.001"/>
      </geometry>
    </collision>
  </link>

  <joint
    name="joint28"
    type="fixed">
    <origin
      xyz="0.20 -0.52 0"
      rpy="1.5708 0 0" />
    <parent
      link="x_ray_generator" />
    <child
      link="x_ray_beam" />
  </joint>

  <link
    name="x_ray_beam">
    <inertial>
      <origin
        xyz="0 0 0"
        rpy="0 0 0" />
      <mass
        value="0.50503" />
      <inertia
        ixx="0.0012932"
        ixy="1.9229E-08"
        ixz="-9.9312E-09"
        iyy="0.0013329"
        iyz="0.00033609"
        izz="0.0015121" />
    </inertial>
    <visual>
      <origin
        xyz="0 0 0"
        rpy="-3.1416 0 0" />
      <geometry>
        <mesh
          filename="package://m20id_35/meshes/cone.STL" scale = "1 1 1"/>
      </geometry>
      <material
        name="">
        <color
          rgba="0.9 0.9 0.9 0.2" />
      </material>
    </visual>
    <collision>
      <origin
        xyz="0 0 0"
        rpy="-3.1416 0 0" />
      <geometry>
        <mesh
          filename="package://m20id_35/meshes/cone.STL"  scale = "1 1 1"/>
      </geometry>
    </collision>
  </link>


  <joint
    name="joint00"
    type="fixed">
    <origin
      xyz="0 0 0"
      rpy="0 0 1.5708" />
    <parent
      link="base_ground" />
    <child
      link="wall" />
  </joint>

  <link
    name="wall">
    <inertial>
      <origin
        xyz="0 0 0 "
        rpy="0 0 1.5708" />
      <mass
        value="1e7" />
      <inertia
        ixx="1e6"
        ixy="1e6"
        ixz="1e6"
        iyy="1e6"
        iyz="1e6"
        izz="1e6" />
    </inertial>
    <visual>
      <origin
        xyz="0 0 0"
        rpy="0 0 0" />
      <geometry>
        <mesh
          filename="package://m20id_35/meshes/wall.STL" scale = "1 1 1"/>
      </geometry>
      <material
        name="">
        <color
          rgba="1.0 0.0 0.0 1.0" />
      </material>
    </visual>
    <collision>
      <origin
        xyz="0 0 0"
        rpy="0 0 0" />
      <geometry>
        <mesh
          filename="package://m20id_35/meshes/wall.STL"  scale = "1 1 1"/>
      </geometry>
    </collision>
  </link>



  <joint
    name="joint01"
    type="fixed">
    <origin
      xyz="0 0 0"
      rpy="0 0 0" />
    <parent
      link="base_ground" />
    <child
      link="floor" />
  </joint>

  <link
    name="floor">
    <inertial>
      <origin
        xyz="0 0 0 "
        rpy="0 0 1.5708" />
      <mass
        value="1e7" />
      <inertia
        ixx="1e6"
        ixy="1e6"
        ixz="1e6"
        iyy="1e6"
        iyz="1e6"
        izz="1e6" />
    </inertial>
    <visual>
      <origin
        xyz="0 0 0"
        rpy="0 0 0" />
      <geometry>
        <mesh
          filename="package://m20id_35/meshes/floor.STL" scale = "1 1 1"/>
      </geometry>
      <material
        name="">
        <color
          rgba="0.8 0.0 0.0 1.0" />
      </material>
    </visual>
    <collision>
      <origin
        xyz="0 0 0.0"
        rpy="0 0 0" />
      <geometry>
        <mesh
          filename="package://m20id_35/meshes/floor.STL"  scale = "1 1 1"/>
      </geometry>
    </collision>
  </link>


  <joint
    name="joint02"
    type="fixed">
    <origin
      xyz="0 0 0"
      rpy="0 0 0" />
    <parent
      link="base_ground" />
    <child
      link="ceil" />
  </joint>

  <link
    name="ceil">
    <inertial>
      <origin
        xyz="0 0 0 "
        rpy="0 0 1.5708" />
      <mass
        value="1e7" />
      <inertia
        ixx="1e6"
        ixy="1e6"
        ixz="1e6"
        iyy="1e6"
        iyz="1e6"
        izz="1e6" />
    </inertial>
    <visual>
      <origin
        xyz="0 0 2.5"
        rpy="0 0 0" />
      <geometry>
        <mesh
          filename="package://m20id_35/meshes/floor.STL" scale = "1 1 1"/>
      </geometry>
      <material
        name="">
        <color
          rgba="0.8 0.0 0.0 0.1" />
      </material>
    </visual>
    <collision>
      <origin
        xyz="0 0 2.5"
        rpy="0 0 0" />
      <geometry>
        <mesh
          filename="package://m20id_35/meshes/floor.STL"  scale = "1 1 1"/>
      </geometry>
    </collision>
  </link>

  <!-- <joint
    name="joint03"
    type="fixed">
    <origin
      xyz="0 0 0"
      rpy="0 0 0" />
    <parent
      link="base_ground" />
    <child
      link="object" />
  </joint>

  <link
    name="object">
    <inertial>
      <origin
        xyz="0 0 0 "
        rpy="0 0 0" />
      <mass
        value="1e7" />
      <inertia
        ixx="1e6"
        ixy="1e6"
        ixz="1e6"
        iyy="1e6"
        iyz="1e6"
        izz="1e6" />
    </inertial>
    <visual>
      <origin
        xyz="-6.5 -4 0.5"
        rpy="0 0 0" />
      <geometry>
        <mesh
          filename="package://m20id_35/meshes/wings_defected.STL" scale = "1 1 1"/>
      </geometry>
      <material
        name="">
        <color
          rgba="0.0 1.0 0.0 1.0" />
      </material>
    </visual>
    <collision>
      <origin
        xyz="-6.5 -4 0.5"
        rpy="0 0 0" />
      <geometry>
        <mesh
          filename="package://m20id_35/meshes/wings_defected.STL"  scale = "1 1 1"/>
      </geometry>
    </collision>
  </link> -->

  <joint
    name="joint04"
    type="fixed">
    <origin
      xyz="1.25 0 2.5"
      rpy="1.5708 0 1.5708" />
    <parent
      link="base_ground" />
    <child
      link="virtual_wall" />
  </joint>

  <link
    name="virtual_wall">
    <inertial>
      <origin
        xyz="0 0 0 "
        rpy="0 0 0" />
      <mass
        value="1e7" />
      <inertia
        ixx="1e6"
        ixy="1e6"
        ixz="1e6"
        iyy="1e6"
        iyz="1e6"
        izz="1e6" />
    </inertial>
    <visual>
      <origin
        xyz="0 0 0"
        rpy="0 0 0" />
      <geometry>
        <mesh
          filename="package://m20id_35/meshes/floor.STL" scale = "1 1 1"/>
      </geometry>
      <material
        name="">
        <color
          rgba="0.0 0.0 1.0 0.5" />
      </material>
    </visual>
    <collision>
      <origin
        xyz="0 0 0"
        rpy="0 0 0" />
      <geometry>
        <mesh
          filename="package://m20id_35/meshes/floor.STL"  scale = "1 1 1"/>
      </geometry>
    </collision>
  </link>

</robot>

